 * Serving Flask app "app" (lazy loading)
 * Environment: production
   WARNING: This is a development server. Do not use it in a production deployment.
   Use a production WSGI server instead.
 * Debug mode: off
 * Running on http://14.49.45.139:8443/ (Press CTRL+C to quit)
WARNING:tensorflow:From /home/user2/stylehub/fashion-graph/fashion_graph/models/base.py:35: The name tf.placeholder is deprecated. Please use tf.compat.v1.placeholder instead.

WARNING:tensorflow:From /home/user2/stylehub/fashion-graph/fashion_graph/models/base.py:37: The name tf.placeholder_with_default is deprecated. Please use tf.compat.v1.placeholder_with_default instead.

WARNING:tensorflow:From /home/user2/stylehub/fashion-graph/fashion_graph/models/base.py:40: The name tf.sparse_placeholder is deprecated. Please use tf.compat.v1.sparse_placeholder instead.

WARNING:tensorflow:From /home/user2/stylehub/fashion-graph/fashion_graph/models/gcn/model/CompatibilityGAE.py:108: The name tf.train.AdamOptimizer is deprecated. Please use tf.compat.v1.train.AdamOptimizer instead.

WARNING:tensorflow:From /home/user2/stylehub/fashion-graph/fashion_graph/models/gcn/model/CompatibilityGAE.py:50: The name tf.variable_scope is deprecated. Please use tf.compat.v1.variable_scope instead.

WARNING:tensorflow:From /home/user2/stylehub/fashion-graph/fashion_graph/models/gcn/model/initializations.py:24: The name tf.random_uniform is deprecated. Please use tf.random.uniform instead.

WARNING:tensorflow:From /home/user2/stylehub/fashion-graph/fashion_graph/models/gcn/model/layers.py:156: calling dropout (from tensorflow.python.ops.nn_ops) with keep_prob is deprecated and will be removed in a future version.
Instructions for updating:
Please use `rate` instead of `keep_prob`. Rate should be set to `rate = 1 - keep_prob`.
WARNING:tensorflow:From /home/user2/stylehub/fashion-graph/fashion_graph/models/gcn/model/layers.py:168: The name tf.sparse_tensor_dense_matmul is deprecated. Please use tf.sparse.sparse_dense_matmul instead.

WARNING:tensorflow:From /home/user2/stylehub/fashion-graph/fashion_graph/models/gcn/model/layers.py:178: batch_normalization (from tensorflow.python.layers.normalization) is deprecated and will be removed in a future version.
Instructions for updating:
Use keras.layers.BatchNormalization instead.  In particular, `tf.control_dependencies(tf.GraphKeys.UPDATE_OPS)` should not be used (consult the `tf.keras.layers.batch_normalization` documentation).
WARNING:tensorflow:From /home/user2/anaconda3/envs/graph/lib/python3.7/site-packages/tensorflow_core/python/layers/normalization.py:327: Layer.apply (from tensorflow.python.keras.engine.base_layer) is deprecated and will be removed in a future version.
Instructions for updating:
Please use `layer.__call__` method instead.
WARNING:tensorflow:From /home/user2/anaconda3/envs/graph/lib/python3.7/site-packages/tensorflow_core/python/ops/nn_impl.py:183: where (from tensorflow.python.ops.array_ops) is deprecated and will be removed in a future version.
Instructions for updating:
Use tf.where in 2.0, which has the same broadcast rule as np.where
WARNING:tensorflow:From /home/user2/stylehub/fashion-graph/fashion_graph/models/gcn/model/CompatibilityGAE.py:118: The name tf.summary.scalar is deprecated. Please use tf.compat.v1.summary.scalar instead.

WARNING:tensorflow:From /home/user2/stylehub/fashion-graph/fashion_graph/models/gcn/model/metrics.py:24: to_int64 (from tensorflow.python.ops.math_ops) is deprecated and will be removed in a future version.
Instructions for updating:
Use `tf.cast` instead.
WARNING:tensorflow:From /home/user2/stylehub/fashion-graph/fashion_graph/models/gcn/model/metrics.py:49: The name tf.confusion_matrix is deprecated. Please use tf.math.confusion_matrix instead.

WARNING:tensorflow:From /home/user2/stylehub/fashion-graph/fashion_graph/models/gcn/model/CompatibilityGAE.py:72: The name tf.get_collection is deprecated. Please use tf.compat.v1.get_collection instead.

WARNING:tensorflow:From /home/user2/stylehub/fashion-graph/fashion_graph/models/gcn/model/CompatibilityGAE.py:72: The name tf.GraphKeys is deprecated. Please use tf.compat.v1.GraphKeys instead.

/home/user2/anaconda3/envs/graph/lib/python3.7/site-packages/tensorflow_core/python/framework/indexed_slices.py:424: UserWarning: Converting sparse IndexedSlices to a dense Tensor of unknown shape. This may consume a large amount of memory.
  "Converting sparse IndexedSlices to a dense Tensor of unknown shape. "
WARNING:tensorflow:From /home/user2/stylehub/fashion-graph/fashion_graph/models/base.py:55: The name tf.train.Saver is deprecated. Please use tf.compat.v1.train.Saver instead.

WARNING:tensorflow:From /home/user2/stylehub/fashion-graph/fashion_graph/models/base.py:56: The name tf.Session is deprecated. Please use tf.compat.v1.Session instead.

2021-08-03 17:18:41.963338: I tensorflow/core/platform/cpu_feature_guard.cc:145] This TensorFlow binary is optimized with Intel(R) MKL-DNN to use the following CPU instructions in performance critical operations:  SSE4.1 SSE4.2 AVX AVX2 AVX512F FMA
To enable them in non-MKL-DNN operations, rebuild TensorFlow with the appropriate compiler flags.
2021-08-03 17:18:41.987494: I tensorflow/core/platform/profile_utils/cpu_utils.cc:94] CPU Frequency: 2294605000 Hz
2021-08-03 17:18:41.988667: I tensorflow/compiler/xla/service/service.cc:168] XLA service 0x7f45e4ba8790 initialized for platform Host (this does not guarantee that XLA will be used). Devices:
2021-08-03 17:18:41.988717: I tensorflow/compiler/xla/service/service.cc:176]   StreamExecutor device (0): Host, Default Version
2021-08-03 17:18:41.989028: I tensorflow/core/common_runtime/process_util.cc:115] Creating new thread pool with default inter op setting: 2. Tune using inter_op_parallelism_threads for best performance.
54.86.50.139 - - [03/Aug/2021 17:18:51] "[37mPOST /styling HTTP/1.1[0m" 200 -
2021-08-03 17:19:02.751738: W tensorflow/core/framework/op_kernel.cc:1651] OP_REQUIRES failed at save_restore_v2_ops.cc:184 : Not found: Key compatibilitygae/gcn_4_vars/weights_n_0 not found in checkpoint
/home/user2/anaconda3/envs/graph/lib/python3.7/site-packages/tensorflow_core/python/framework/indexed_slices.py:424: UserWarning: Converting sparse IndexedSlices to a dense Tensor of unknown shape. This may consume a large amount of memory.
  "Converting sparse IndexedSlices to a dense Tensor of unknown shape. "
[2021-08-03 17:19:02,787] ERROR in app: Exception on /styling [POST]
Traceback (most recent call last):
  File "/home/user2/anaconda3/envs/graph/lib/python3.7/site-packages/tensorflow_core/python/client/session.py", line 1365, in _do_call
    return fn(*args)
  File "/home/user2/anaconda3/envs/graph/lib/python3.7/site-packages/tensorflow_core/python/client/session.py", line 1350, in _run_fn
    target_list, run_metadata)
  File "/home/user2/anaconda3/envs/graph/lib/python3.7/site-packages/tensorflow_core/python/client/session.py", line 1443, in _call_tf_sessionrun
    run_metadata)
tensorflow.python.framework.errors_impl.NotFoundError: Key compatibilitygae/gcn_4_vars/weights_n_0 not found in checkpoint
	 [[{{node save/RestoreV2}}]]

During handling of the above exception, another exception occurred:

Traceback (most recent call last):
  File "/home/user2/anaconda3/envs/graph/lib/python3.7/site-packages/tensorflow_core/python/training/saver.py", line 1290, in restore
    {self.saver_def.filename_tensor_name: save_path})
  File "/home/user2/anaconda3/envs/graph/lib/python3.7/site-packages/tensorflow_core/python/client/session.py", line 956, in run
    run_metadata_ptr)
  File "/home/user2/anaconda3/envs/graph/lib/python3.7/site-packages/tensorflow_core/python/client/session.py", line 1180, in _run
    feed_dict_tensor, options, run_metadata)
  File "/home/user2/anaconda3/envs/graph/lib/python3.7/site-packages/tensorflow_core/python/client/session.py", line 1359, in _do_run
    run_metadata)
  File "/home/user2/anaconda3/envs/graph/lib/python3.7/site-packages/tensorflow_core/python/client/session.py", line 1384, in _do_call
    raise type(e)(node_def, op, message)
tensorflow.python.framework.errors_impl.NotFoundError: Key compatibilitygae/gcn_4_vars/weights_n_0 not found in checkpoint
	 [[node save/RestoreV2 (defined at /home/user2/anaconda3/envs/graph/lib/python3.7/site-packages/tensorflow_core/python/framework/ops.py:1748) ]]

Original stack trace for 'save/RestoreV2':
  File "/home/user2/anaconda3/envs/graph/lib/python3.7/threading.py", line 890, in _bootstrap
    self._bootstrap_inner()
  File "/home/user2/anaconda3/envs/graph/lib/python3.7/threading.py", line 926, in _bootstrap_inner
    self.run()
  File "/home/user2/anaconda3/envs/graph/lib/python3.7/threading.py", line 870, in run
    self._target(*self._args, **self._kwargs)
  File "/home/user2/anaconda3/envs/graph/lib/python3.7/socketserver.py", line 650, in process_request_thread
    self.finish_request(request, client_address)
  File "/home/user2/anaconda3/envs/graph/lib/python3.7/socketserver.py", line 360, in finish_request
    self.RequestHandlerClass(request, client_address, self)
  File "/home/user2/anaconda3/envs/graph/lib/python3.7/socketserver.py", line 720, in __init__
    self.handle()
  File "/home/user2/anaconda3/envs/graph/lib/python3.7/site-packages/werkzeug/serving.py", line 329, in handle
    rv = BaseHTTPRequestHandler.handle(self)
  File "/home/user2/anaconda3/envs/graph/lib/python3.7/http/server.py", line 426, in handle
    self.handle_one_request()
  File "/home/user2/anaconda3/envs/graph/lib/python3.7/site-packages/werkzeug/serving.py", line 364, in handle_one_request
    return self.run_wsgi()
  File "/home/user2/anaconda3/envs/graph/lib/python3.7/site-packages/werkzeug/serving.py", line 306, in run_wsgi
    execute(self.server.app)
  File "/home/user2/anaconda3/envs/graph/lib/python3.7/site-packages/werkzeug/serving.py", line 294, in execute
    application_iter = app(environ, start_response)
  File "/home/user2/anaconda3/envs/graph/lib/python3.7/site-packages/flask/app.py", line 2464, in __call__
    return self.wsgi_app(environ, start_response)
  File "/home/user2/anaconda3/envs/graph/lib/python3.7/site-packages/flask/app.py", line 2447, in wsgi_app
    response = self.full_dispatch_request()
  File "/home/user2/anaconda3/envs/graph/lib/python3.7/site-packages/flask/app.py", line 1950, in full_dispatch_request
    rv = self.dispatch_request()
  File "/home/user2/anaconda3/envs/graph/lib/python3.7/site-packages/flask/app.py", line 1936, in dispatch_request
    return self.view_functions[rule.endpoint](**req.view_args)
  File "app.py", line 31, in get_result
    recommender = GraphRecommender(model_dir=MODEL_DIR)
  File "/home/user2/stylehub/fashion-graph/fashion_graph/models/recommend.py", line 20, in __init__
    super().__init__(model_dir, model_config)
  File "/home/user2/stylehub/fashion-graph/fashion_graph/models/base.py", line 55, in __init__
    self.saver = tf.train.Saver()
  File "/home/user2/anaconda3/envs/graph/lib/python3.7/site-packages/tensorflow_core/python/training/saver.py", line 828, in __init__
    self.build()
  File "/home/user2/anaconda3/envs/graph/lib/python3.7/site-packages/tensorflow_core/python/training/saver.py", line 840, in build
    self._build(self._filename, build_save=True, build_restore=True)
  File "/home/user2/anaconda3/envs/graph/lib/python3.7/site-packages/tensorflow_core/python/training/saver.py", line 878, in _build
    build_restore=build_restore)
  File "/home/user2/anaconda3/envs/graph/lib/python3.7/site-packages/tensorflow_core/python/training/saver.py", line 508, in _build_internal
    restore_sequentially, reshape)
  File "/home/user2/anaconda3/envs/graph/lib/python3.7/site-packages/tensorflow_core/python/training/saver.py", line 328, in _AddRestoreOps
    restore_sequentially)
  File "/home/user2/anaconda3/envs/graph/lib/python3.7/site-packages/tensorflow_core/python/training/saver.py", line 575, in bulk_restore
    return io_ops.restore_v2(filename_tensor, names, slices, dtypes)
  File "/home/user2/anaconda3/envs/graph/lib/python3.7/site-packages/tensorflow_core/python/ops/gen_io_ops.py", line 1696, in restore_v2
    name=name)
  File "/home/user2/anaconda3/envs/graph/lib/python3.7/site-packages/tensorflow_core/python/framework/op_def_library.py", line 794, in _apply_op_helper
    op_def=op_def)
  File "/home/user2/anaconda3/envs/graph/lib/python3.7/site-packages/tensorflow_core/python/util/deprecation.py", line 507, in new_func
    return func(*args, **kwargs)
  File "/home/user2/anaconda3/envs/graph/lib/python3.7/site-packages/tensorflow_core/python/framework/ops.py", line 3357, in create_op
    attrs, op_def, compute_device)
  File "/home/user2/anaconda3/envs/graph/lib/python3.7/site-packages/tensorflow_core/python/framework/ops.py", line 3426, in _create_op_internal
    op_def=op_def)
  File "/home/user2/anaconda3/envs/graph/lib/python3.7/site-packages/tensorflow_core/python/framework/ops.py", line 1748, in __init__
    self._traceback = tf_stack.extract_stack()


During handling of the above exception, another exception occurred:

Traceback (most recent call last):
  File "/home/user2/anaconda3/envs/graph/lib/python3.7/site-packages/tensorflow_core/python/training/saver.py", line 1300, in restore
    names_to_keys = object_graph_key_mapping(save_path)
  File "/home/user2/anaconda3/envs/graph/lib/python3.7/site-packages/tensorflow_core/python/training/saver.py", line 1618, in object_graph_key_mapping
    object_graph_string = reader.get_tensor(trackable.OBJECT_GRAPH_PROTO_KEY)
  File "/home/user2/anaconda3/envs/graph/lib/python3.7/site-packages/tensorflow_core/python/pywrap_tensorflow_internal.py", line 915, in get_tensor
    return CheckpointReader_GetTensor(self, compat.as_bytes(tensor_str))
tensorflow.python.framework.errors_impl.NotFoundError: Key _CHECKPOINTABLE_OBJECT_GRAPH not found in checkpoint

During handling of the above exception, another exception occurred:

Traceback (most recent call last):
  File "/home/user2/anaconda3/envs/graph/lib/python3.7/site-packages/flask/app.py", line 2447, in wsgi_app
    response = self.full_dispatch_request()
  File "/home/user2/anaconda3/envs/graph/lib/python3.7/site-packages/flask/app.py", line 1952, in full_dispatch_request
    rv = self.handle_user_exception(e)
  File "/home/user2/anaconda3/envs/graph/lib/python3.7/site-packages/flask/app.py", line 1821, in handle_user_exception
    reraise(exc_type, exc_value, tb)
  File "/home/user2/anaconda3/envs/graph/lib/python3.7/site-packages/flask/_compat.py", line 39, in reraise
    raise value
  File "/home/user2/anaconda3/envs/graph/lib/python3.7/site-packages/flask/app.py", line 1950, in full_dispatch_request
    rv = self.dispatch_request()
  File "/home/user2/anaconda3/envs/graph/lib/python3.7/site-packages/flask/app.py", line 1936, in dispatch_request
    return self.view_functions[rule.endpoint](**req.view_args)
  File "app.py", line 31, in get_result
    recommender = GraphRecommender(model_dir=MODEL_DIR)
  File "/home/user2/stylehub/fashion-graph/fashion_graph/models/recommend.py", line 20, in __init__
    super().__init__(model_dir, model_config)
  File "/home/user2/stylehub/fashion-graph/fashion_graph/models/base.py", line 57, in __init__
    self.saver.restore(self.session, model_path)
  File "/home/user2/anaconda3/envs/graph/lib/python3.7/site-packages/tensorflow_core/python/training/saver.py", line 1306, in restore
    err, "a Variable name or other graph key that is missing")
tensorflow.python.framework.errors_impl.NotFoundError: Restoring from checkpoint failed. This is most likely due to a Variable name or other graph key that is missing from the checkpoint. Please ensure that you have not altered the graph expected based on the checkpoint. Original error:

Key compatibilitygae/gcn_4_vars/weights_n_0 not found in checkpoint
	 [[node save/RestoreV2 (defined at /home/user2/anaconda3/envs/graph/lib/python3.7/site-packages/tensorflow_core/python/framework/ops.py:1748) ]]

Original stack trace for 'save/RestoreV2':
  File "/home/user2/anaconda3/envs/graph/lib/python3.7/threading.py", line 890, in _bootstrap
    self._bootstrap_inner()
  File "/home/user2/anaconda3/envs/graph/lib/python3.7/threading.py", line 926, in _bootstrap_inner
    self.run()
  File "/home/user2/anaconda3/envs/graph/lib/python3.7/threading.py", line 870, in run
    self._target(*self._args, **self._kwargs)
  File "/home/user2/anaconda3/envs/graph/lib/python3.7/socketserver.py", line 650, in process_request_thread
    self.finish_request(request, client_address)
  File "/home/user2/anaconda3/envs/graph/lib/python3.7/socketserver.py", line 360, in finish_request
    self.RequestHandlerClass(request, client_address, self)
  File "/home/user2/anaconda3/envs/graph/lib/python3.7/socketserver.py", line 720, in __init__
    self.handle()
  File "/home/user2/anaconda3/envs/graph/lib/python3.7/site-packages/werkzeug/serving.py", line 329, in handle
    rv = BaseHTTPRequestHandler.handle(self)
  File "/home/user2/anaconda3/envs/graph/lib/python3.7/http/server.py", line 426, in handle
    self.handle_one_request()
  File "/home/user2/anaconda3/envs/graph/lib/python3.7/site-packages/werkzeug/serving.py", line 364, in handle_one_request
    return self.run_wsgi()
  File "/home/user2/anaconda3/envs/graph/lib/python3.7/site-packages/werkzeug/serving.py", line 306, in run_wsgi
    execute(self.server.app)
  File "/home/user2/anaconda3/envs/graph/lib/python3.7/site-packages/werkzeug/serving.py", line 294, in execute
    application_iter = app(environ, start_response)
  File "/home/user2/anaconda3/envs/graph/lib/python3.7/site-packages/flask/app.py", line 2464, in __call__
    return self.wsgi_app(environ, start_response)
  File "/home/user2/anaconda3/envs/graph/lib/python3.7/site-packages/flask/app.py", line 2447, in wsgi_app
    response = self.full_dispatch_request()
  File "/home/user2/anaconda3/envs/graph/lib/python3.7/site-packages/flask/app.py", line 1950, in full_dispatch_request
    rv = self.dispatch_request()
  File "/home/user2/anaconda3/envs/graph/lib/python3.7/site-packages/flask/app.py", line 1936, in dispatch_request
    return self.view_functions[rule.endpoint](**req.view_args)
  File "app.py", line 31, in get_result
    recommender = GraphRecommender(model_dir=MODEL_DIR)
  File "/home/user2/stylehub/fashion-graph/fashion_graph/models/recommend.py", line 20, in __init__
    super().__init__(model_dir, model_config)
  File "/home/user2/stylehub/fashion-graph/fashion_graph/models/base.py", line 55, in __init__
    self.saver = tf.train.Saver()
  File "/home/user2/anaconda3/envs/graph/lib/python3.7/site-packages/tensorflow_core/python/training/saver.py", line 828, in __init__
    self.build()
  File "/home/user2/anaconda3/envs/graph/lib/python3.7/site-packages/tensorflow_core/python/training/saver.py", line 840, in build
    self._build(self._filename, build_save=True, build_restore=True)
  File "/home/user2/anaconda3/envs/graph/lib/python3.7/site-packages/tensorflow_core/python/training/saver.py", line 878, in _build
    build_restore=build_restore)
  File "/home/user2/anaconda3/envs/graph/lib/python3.7/site-packages/tensorflow_core/python/training/saver.py", line 508, in _build_internal
    restore_sequentially, reshape)
  File "/home/user2/anaconda3/envs/graph/lib/python3.7/site-packages/tensorflow_core/python/training/saver.py", line 328, in _AddRestoreOps
    restore_sequentially)
  File "/home/user2/anaconda3/envs/graph/lib/python3.7/site-packages/tensorflow_core/python/training/saver.py", line 575, in bulk_restore
    return io_ops.restore_v2(filename_tensor, names, slices, dtypes)
  File "/home/user2/anaconda3/envs/graph/lib/python3.7/site-packages/tensorflow_core/python/ops/gen_io_ops.py", line 1696, in restore_v2
    name=name)
  File "/home/user2/anaconda3/envs/graph/lib/python3.7/site-packages/tensorflow_core/python/framework/op_def_library.py", line 794, in _apply_op_helper
    op_def=op_def)
  File "/home/user2/anaconda3/envs/graph/lib/python3.7/site-packages/tensorflow_core/python/util/deprecation.py", line 507, in new_func
    return func(*args, **kwargs)
  File "/home/user2/anaconda3/envs/graph/lib/python3.7/site-packages/tensorflow_core/python/framework/ops.py", line 3357, in create_op
    attrs, op_def, compute_device)
  File "/home/user2/anaconda3/envs/graph/lib/python3.7/site-packages/tensorflow_core/python/framework/ops.py", line 3426, in _create_op_internal
    op_def=op_def)
  File "/home/user2/anaconda3/envs/graph/lib/python3.7/site-packages/tensorflow_core/python/framework/ops.py", line 1748, in __init__
    self._traceback = tf_stack.extract_stack()

54.86.50.139 - - [03/Aug/2021 17:19:02] "[1m[35mPOST /styling HTTP/1.1[0m" 500 -
2021-08-03 17:19:19.307219: W tensorflow/core/framework/op_kernel.cc:1651] OP_REQUIRES failed at save_restore_v2_ops.cc:184 : Not found: Key compatibilitygae/gcn_7_vars/weights_n_0 not found in checkpoint
/home/user2/anaconda3/envs/graph/lib/python3.7/site-packages/tensorflow_core/python/framework/indexed_slices.py:424: UserWarning: Converting sparse IndexedSlices to a dense Tensor of unknown shape. This may consume a large amount of memory.
  "Converting sparse IndexedSlices to a dense Tensor of unknown shape. "
[2021-08-03 17:19:19,316] ERROR in app: Exception on /styling [POST]
Traceback (most recent call last):
  File "/home/user2/anaconda3/envs/graph/lib/python3.7/site-packages/tensorflow_core/python/client/session.py", line 1365, in _do_call
    return fn(*args)
  File "/home/user2/anaconda3/envs/graph/lib/python3.7/site-packages/tensorflow_core/python/client/session.py", line 1350, in _run_fn
    target_list, run_metadata)
  File "/home/user2/anaconda3/envs/graph/lib/python3.7/site-packages/tensorflow_core/python/client/session.py", line 1443, in _call_tf_sessionrun
    run_metadata)
tensorflow.python.framework.errors_impl.NotFoundError: Key compatibilitygae/gcn_7_vars/weights_n_0 not found in checkpoint
	 [[{{node save/RestoreV2}}]]

During handling of the above exception, another exception occurred:

Traceback (most recent call last):
  File "/home/user2/anaconda3/envs/graph/lib/python3.7/site-packages/tensorflow_core/python/training/saver.py", line 1290, in restore
    {self.saver_def.filename_tensor_name: save_path})
  File "/home/user2/anaconda3/envs/graph/lib/python3.7/site-packages/tensorflow_core/python/client/session.py", line 956, in run
    run_metadata_ptr)
  File "/home/user2/anaconda3/envs/graph/lib/python3.7/site-packages/tensorflow_core/python/client/session.py", line 1180, in _run
    feed_dict_tensor, options, run_metadata)
  File "/home/user2/anaconda3/envs/graph/lib/python3.7/site-packages/tensorflow_core/python/client/session.py", line 1359, in _do_run
    run_metadata)
  File "/home/user2/anaconda3/envs/graph/lib/python3.7/site-packages/tensorflow_core/python/client/session.py", line 1384, in _do_call
    raise type(e)(node_def, op, message)
tensorflow.python.framework.errors_impl.NotFoundError: Key compatibilitygae/gcn_7_vars/weights_n_0 not found in checkpoint
	 [[node save/RestoreV2 (defined at /home/user2/anaconda3/envs/graph/lib/python3.7/site-packages/tensorflow_core/python/framework/ops.py:1748) ]]

Original stack trace for 'save/RestoreV2':
  File "/home/user2/anaconda3/envs/graph/lib/python3.7/threading.py", line 890, in _bootstrap
    self._bootstrap_inner()
  File "/home/user2/anaconda3/envs/graph/lib/python3.7/threading.py", line 926, in _bootstrap_inner
    self.run()
  File "/home/user2/anaconda3/envs/graph/lib/python3.7/threading.py", line 870, in run
    self._target(*self._args, **self._kwargs)
  File "/home/user2/anaconda3/envs/graph/lib/python3.7/socketserver.py", line 650, in process_request_thread
    self.finish_request(request, client_address)
  File "/home/user2/anaconda3/envs/graph/lib/python3.7/socketserver.py", line 360, in finish_request
    self.RequestHandlerClass(request, client_address, self)
  File "/home/user2/anaconda3/envs/graph/lib/python3.7/socketserver.py", line 720, in __init__
    self.handle()
  File "/home/user2/anaconda3/envs/graph/lib/python3.7/site-packages/werkzeug/serving.py", line 329, in handle
    rv = BaseHTTPRequestHandler.handle(self)
  File "/home/user2/anaconda3/envs/graph/lib/python3.7/http/server.py", line 426, in handle
    self.handle_one_request()
  File "/home/user2/anaconda3/envs/graph/lib/python3.7/site-packages/werkzeug/serving.py", line 364, in handle_one_request
    return self.run_wsgi()
  File "/home/user2/anaconda3/envs/graph/lib/python3.7/site-packages/werkzeug/serving.py", line 306, in run_wsgi
    execute(self.server.app)
  File "/home/user2/anaconda3/envs/graph/lib/python3.7/site-packages/werkzeug/serving.py", line 294, in execute
    application_iter = app(environ, start_response)
  File "/home/user2/anaconda3/envs/graph/lib/python3.7/site-packages/flask/app.py", line 2464, in __call__
    return self.wsgi_app(environ, start_response)
  File "/home/user2/anaconda3/envs/graph/lib/python3.7/site-packages/flask/app.py", line 2447, in wsgi_app
    response = self.full_dispatch_request()
  File "/home/user2/anaconda3/envs/graph/lib/python3.7/site-packages/flask/app.py", line 1950, in full_dispatch_request
    rv = self.dispatch_request()
  File "/home/user2/anaconda3/envs/graph/lib/python3.7/site-packages/flask/app.py", line 1936, in dispatch_request
    return self.view_functions[rule.endpoint](**req.view_args)
  File "app.py", line 31, in get_result
    recommender = GraphRecommender(model_dir=MODEL_DIR)
  File "/home/user2/stylehub/fashion-graph/fashion_graph/models/recommend.py", line 20, in __init__
    super().__init__(model_dir, model_config)
  File "/home/user2/stylehub/fashion-graph/fashion_graph/models/base.py", line 55, in __init__
    self.saver = tf.train.Saver()
  File "/home/user2/anaconda3/envs/graph/lib/python3.7/site-packages/tensorflow_core/python/training/saver.py", line 828, in __init__
    self.build()
  File "/home/user2/anaconda3/envs/graph/lib/python3.7/site-packages/tensorflow_core/python/training/saver.py", line 840, in build
    self._build(self._filename, build_save=True, build_restore=True)
  File "/home/user2/anaconda3/envs/graph/lib/python3.7/site-packages/tensorflow_core/python/training/saver.py", line 878, in _build
    build_restore=build_restore)
  File "/home/user2/anaconda3/envs/graph/lib/python3.7/site-packages/tensorflow_core/python/training/saver.py", line 508, in _build_internal
    restore_sequentially, reshape)
  File "/home/user2/anaconda3/envs/graph/lib/python3.7/site-packages/tensorflow_core/python/training/saver.py", line 328, in _AddRestoreOps
    restore_sequentially)
  File "/home/user2/anaconda3/envs/graph/lib/python3.7/site-packages/tensorflow_core/python/training/saver.py", line 575, in bulk_restore
    return io_ops.restore_v2(filename_tensor, names, slices, dtypes)
  File "/home/user2/anaconda3/envs/graph/lib/python3.7/site-packages/tensorflow_core/python/ops/gen_io_ops.py", line 1696, in restore_v2
    name=name)
  File "/home/user2/anaconda3/envs/graph/lib/python3.7/site-packages/tensorflow_core/python/framework/op_def_library.py", line 794, in _apply_op_helper
    op_def=op_def)
  File "/home/user2/anaconda3/envs/graph/lib/python3.7/site-packages/tensorflow_core/python/util/deprecation.py", line 507, in new_func
    return func(*args, **kwargs)
  File "/home/user2/anaconda3/envs/graph/lib/python3.7/site-packages/tensorflow_core/python/framework/ops.py", line 3357, in create_op
    attrs, op_def, compute_device)
  File "/home/user2/anaconda3/envs/graph/lib/python3.7/site-packages/tensorflow_core/python/framework/ops.py", line 3426, in _create_op_internal
    op_def=op_def)
  File "/home/user2/anaconda3/envs/graph/lib/python3.7/site-packages/tensorflow_core/python/framework/ops.py", line 1748, in __init__
    self._traceback = tf_stack.extract_stack()


During handling of the above exception, another exception occurred:

Traceback (most recent call last):
  File "/home/user2/anaconda3/envs/graph/lib/python3.7/site-packages/tensorflow_core/python/training/saver.py", line 1300, in restore
    names_to_keys = object_graph_key_mapping(save_path)
  File "/home/user2/anaconda3/envs/graph/lib/python3.7/site-packages/tensorflow_core/python/training/saver.py", line 1618, in object_graph_key_mapping
    object_graph_string = reader.get_tensor(trackable.OBJECT_GRAPH_PROTO_KEY)
  File "/home/user2/anaconda3/envs/graph/lib/python3.7/site-packages/tensorflow_core/python/pywrap_tensorflow_internal.py", line 915, in get_tensor
    return CheckpointReader_GetTensor(self, compat.as_bytes(tensor_str))
tensorflow.python.framework.errors_impl.NotFoundError: Key _CHECKPOINTABLE_OBJECT_GRAPH not found in checkpoint

During handling of the above exception, another exception occurred:

Traceback (most recent call last):
  File "/home/user2/anaconda3/envs/graph/lib/python3.7/site-packages/flask/app.py", line 2447, in wsgi_app
    response = self.full_dispatch_request()
  File "/home/user2/anaconda3/envs/graph/lib/python3.7/site-packages/flask/app.py", line 1952, in full_dispatch_request
    rv = self.handle_user_exception(e)
  File "/home/user2/anaconda3/envs/graph/lib/python3.7/site-packages/flask/app.py", line 1821, in handle_user_exception
    reraise(exc_type, exc_value, tb)
  File "/home/user2/anaconda3/envs/graph/lib/python3.7/site-packages/flask/_compat.py", line 39, in reraise
    raise value
  File "/home/user2/anaconda3/envs/graph/lib/python3.7/site-packages/flask/app.py", line 1950, in full_dispatch_request
    rv = self.dispatch_request()
  File "/home/user2/anaconda3/envs/graph/lib/python3.7/site-packages/flask/app.py", line 1936, in dispatch_request
    return self.view_functions[rule.endpoint](**req.view_args)
  File "app.py", line 31, in get_result
    recommender = GraphRecommender(model_dir=MODEL_DIR)
  File "/home/user2/stylehub/fashion-graph/fashion_graph/models/recommend.py", line 20, in __init__
    super().__init__(model_dir, model_config)
  File "/home/user2/stylehub/fashion-graph/fashion_graph/models/base.py", line 57, in __init__
    self.saver.restore(self.session, model_path)
  File "/home/user2/anaconda3/envs/graph/lib/python3.7/site-packages/tensorflow_core/python/training/saver.py", line 1306, in restore
    err, "a Variable name or other graph key that is missing")
tensorflow.python.framework.errors_impl.NotFoundError: Restoring from checkpoint failed. This is most likely due to a Variable name or other graph key that is missing from the checkpoint. Please ensure that you have not altered the graph expected based on the checkpoint. Original error:

Key compatibilitygae/gcn_7_vars/weights_n_0 not found in checkpoint
	 [[node save/RestoreV2 (defined at /home/user2/anaconda3/envs/graph/lib/python3.7/site-packages/tensorflow_core/python/framework/ops.py:1748) ]]

Original stack trace for 'save/RestoreV2':
  File "/home/user2/anaconda3/envs/graph/lib/python3.7/threading.py", line 890, in _bootstrap
    self._bootstrap_inner()
  File "/home/user2/anaconda3/envs/graph/lib/python3.7/threading.py", line 926, in _bootstrap_inner
    self.run()
  File "/home/user2/anaconda3/envs/graph/lib/python3.7/threading.py", line 870, in run
    self._target(*self._args, **self._kwargs)
  File "/home/user2/anaconda3/envs/graph/lib/python3.7/socketserver.py", line 650, in process_request_thread
    self.finish_request(request, client_address)
  File "/home/user2/anaconda3/envs/graph/lib/python3.7/socketserver.py", line 360, in finish_request
    self.RequestHandlerClass(request, client_address, self)
  File "/home/user2/anaconda3/envs/graph/lib/python3.7/socketserver.py", line 720, in __init__
    self.handle()
  File "/home/user2/anaconda3/envs/graph/lib/python3.7/site-packages/werkzeug/serving.py", line 329, in handle
    rv = BaseHTTPRequestHandler.handle(self)
  File "/home/user2/anaconda3/envs/graph/lib/python3.7/http/server.py", line 426, in handle
    self.handle_one_request()
  File "/home/user2/anaconda3/envs/graph/lib/python3.7/site-packages/werkzeug/serving.py", line 364, in handle_one_request
    return self.run_wsgi()
  File "/home/user2/anaconda3/envs/graph/lib/python3.7/site-packages/werkzeug/serving.py", line 306, in run_wsgi
    execute(self.server.app)
  File "/home/user2/anaconda3/envs/graph/lib/python3.7/site-packages/werkzeug/serving.py", line 294, in execute
    application_iter = app(environ, start_response)
  File "/home/user2/anaconda3/envs/graph/lib/python3.7/site-packages/flask/app.py", line 2464, in __call__
    return self.wsgi_app(environ, start_response)
  File "/home/user2/anaconda3/envs/graph/lib/python3.7/site-packages/flask/app.py", line 2447, in wsgi_app
    response = self.full_dispatch_request()
  File "/home/user2/anaconda3/envs/graph/lib/python3.7/site-packages/flask/app.py", line 1950, in full_dispatch_request
    rv = self.dispatch_request()
  File "/home/user2/anaconda3/envs/graph/lib/python3.7/site-packages/flask/app.py", line 1936, in dispatch_request
    return self.view_functions[rule.endpoint](**req.view_args)
  File "app.py", line 31, in get_result
    recommender = GraphRecommender(model_dir=MODEL_DIR)
  File "/home/user2/stylehub/fashion-graph/fashion_graph/models/recommend.py", line 20, in __init__
    super().__init__(model_dir, model_config)
  File "/home/user2/stylehub/fashion-graph/fashion_graph/models/base.py", line 55, in __init__
    self.saver = tf.train.Saver()
  File "/home/user2/anaconda3/envs/graph/lib/python3.7/site-packages/tensorflow_core/python/training/saver.py", line 828, in __init__
    self.build()
  File "/home/user2/anaconda3/envs/graph/lib/python3.7/site-packages/tensorflow_core/python/training/saver.py", line 840, in build
    self._build(self._filename, build_save=True, build_restore=True)
  File "/home/user2/anaconda3/envs/graph/lib/python3.7/site-packages/tensorflow_core/python/training/saver.py", line 878, in _build
    build_restore=build_restore)
  File "/home/user2/anaconda3/envs/graph/lib/python3.7/site-packages/tensorflow_core/python/training/saver.py", line 508, in _build_internal
    restore_sequentially, reshape)
  File "/home/user2/anaconda3/envs/graph/lib/python3.7/site-packages/tensorflow_core/python/training/saver.py", line 328, in _AddRestoreOps
    restore_sequentially)
  File "/home/user2/anaconda3/envs/graph/lib/python3.7/site-packages/tensorflow_core/python/training/saver.py", line 575, in bulk_restore
    return io_ops.restore_v2(filename_tensor, names, slices, dtypes)
  File "/home/user2/anaconda3/envs/graph/lib/python3.7/site-packages/tensorflow_core/python/ops/gen_io_ops.py", line 1696, in restore_v2
    name=name)
  File "/home/user2/anaconda3/envs/graph/lib/python3.7/site-packages/tensorflow_core/python/framework/op_def_library.py", line 794, in _apply_op_helper
    op_def=op_def)
  File "/home/user2/anaconda3/envs/graph/lib/python3.7/site-packages/tensorflow_core/python/util/deprecation.py", line 507, in new_func
    return func(*args, **kwargs)
  File "/home/user2/anaconda3/envs/graph/lib/python3.7/site-packages/tensorflow_core/python/framework/ops.py", line 3357, in create_op
    attrs, op_def, compute_device)
  File "/home/user2/anaconda3/envs/graph/lib/python3.7/site-packages/tensorflow_core/python/framework/ops.py", line 3426, in _create_op_internal
    op_def=op_def)
  File "/home/user2/anaconda3/envs/graph/lib/python3.7/site-packages/tensorflow_core/python/framework/ops.py", line 1748, in __init__
    self._traceback = tf_stack.extract_stack()

54.86.50.139 - - [03/Aug/2021 17:19:19] "[1m[35mPOST /styling HTTP/1.1[0m" 500 -
138.246.253.24 - - [03/Aug/2021 17:21:05] code 400, message Bad request version ('P£Ë\x90KëÀÜ\x91Ê<\x8c.')
138.246.253.24 - - [03/Aug/2021 17:21:05] "[1m[35m ø  ô P£ËKëÀÜÊ<.[0m" HTTPStatus.BAD_REQUEST -
2021-08-03 17:21:08.195729: W tensorflow/core/framework/op_kernel.cc:1651] OP_REQUIRES failed at save_restore_v2_ops.cc:184 : Not found: Key compatibilitygae/gcn_10_vars/weights_n_0 not found in checkpoint
/home/user2/anaconda3/envs/graph/lib/python3.7/site-packages/tensorflow_core/python/framework/indexed_slices.py:424: UserWarning: Converting sparse IndexedSlices to a dense Tensor of unknown shape. This may consume a large amount of memory.
  "Converting sparse IndexedSlices to a dense Tensor of unknown shape. "
[2021-08-03 17:21:08,223] ERROR in app: Exception on /styling [POST]
Traceback (most recent call last):
  File "/home/user2/anaconda3/envs/graph/lib/python3.7/site-packages/tensorflow_core/python/client/session.py", line 1365, in _do_call
    return fn(*args)
  File "/home/user2/anaconda3/envs/graph/lib/python3.7/site-packages/tensorflow_core/python/client/session.py", line 1350, in _run_fn
    target_list, run_metadata)
  File "/home/user2/anaconda3/envs/graph/lib/python3.7/site-packages/tensorflow_core/python/client/session.py", line 1443, in _call_tf_sessionrun
    run_metadata)
tensorflow.python.framework.errors_impl.NotFoundError: Key compatibilitygae/gcn_10_vars/weights_n_0 not found in checkpoint
	 [[{{node save/RestoreV2}}]]

During handling of the above exception, another exception occurred:

Traceback (most recent call last):
  File "/home/user2/anaconda3/envs/graph/lib/python3.7/site-packages/tensorflow_core/python/training/saver.py", line 1290, in restore
    {self.saver_def.filename_tensor_name: save_path})
  File "/home/user2/anaconda3/envs/graph/lib/python3.7/site-packages/tensorflow_core/python/client/session.py", line 956, in run
    run_metadata_ptr)
  File "/home/user2/anaconda3/envs/graph/lib/python3.7/site-packages/tensorflow_core/python/client/session.py", line 1180, in _run
    feed_dict_tensor, options, run_metadata)
  File "/home/user2/anaconda3/envs/graph/lib/python3.7/site-packages/tensorflow_core/python/client/session.py", line 1359, in _do_run
    run_metadata)
  File "/home/user2/anaconda3/envs/graph/lib/python3.7/site-packages/tensorflow_core/python/client/session.py", line 1384, in _do_call
    raise type(e)(node_def, op, message)
tensorflow.python.framework.errors_impl.NotFoundError: Key compatibilitygae/gcn_10_vars/weights_n_0 not found in checkpoint
	 [[node save/RestoreV2 (defined at /home/user2/anaconda3/envs/graph/lib/python3.7/site-packages/tensorflow_core/python/framework/ops.py:1748) ]]

Original stack trace for 'save/RestoreV2':
  File "/home/user2/anaconda3/envs/graph/lib/python3.7/threading.py", line 890, in _bootstrap
    self._bootstrap_inner()
  File "/home/user2/anaconda3/envs/graph/lib/python3.7/threading.py", line 926, in _bootstrap_inner
    self.run()
  File "/home/user2/anaconda3/envs/graph/lib/python3.7/threading.py", line 870, in run
    self._target(*self._args, **self._kwargs)
  File "/home/user2/anaconda3/envs/graph/lib/python3.7/socketserver.py", line 650, in process_request_thread
    self.finish_request(request, client_address)
  File "/home/user2/anaconda3/envs/graph/lib/python3.7/socketserver.py", line 360, in finish_request
    self.RequestHandlerClass(request, client_address, self)
  File "/home/user2/anaconda3/envs/graph/lib/python3.7/socketserver.py", line 720, in __init__
    self.handle()
  File "/home/user2/anaconda3/envs/graph/lib/python3.7/site-packages/werkzeug/serving.py", line 329, in handle
    rv = BaseHTTPRequestHandler.handle(self)
  File "/home/user2/anaconda3/envs/graph/lib/python3.7/http/server.py", line 426, in handle
    self.handle_one_request()
  File "/home/user2/anaconda3/envs/graph/lib/python3.7/site-packages/werkzeug/serving.py", line 364, in handle_one_request
    return self.run_wsgi()
  File "/home/user2/anaconda3/envs/graph/lib/python3.7/site-packages/werkzeug/serving.py", line 306, in run_wsgi
    execute(self.server.app)
  File "/home/user2/anaconda3/envs/graph/lib/python3.7/site-packages/werkzeug/serving.py", line 294, in execute
    application_iter = app(environ, start_response)
  File "/home/user2/anaconda3/envs/graph/lib/python3.7/site-packages/flask/app.py", line 2464, in __call__
    return self.wsgi_app(environ, start_response)
  File "/home/user2/anaconda3/envs/graph/lib/python3.7/site-packages/flask/app.py", line 2447, in wsgi_app
    response = self.full_dispatch_request()
  File "/home/user2/anaconda3/envs/graph/lib/python3.7/site-packages/flask/app.py", line 1950, in full_dispatch_request
    rv = self.dispatch_request()
  File "/home/user2/anaconda3/envs/graph/lib/python3.7/site-packages/flask/app.py", line 1936, in dispatch_request
    return self.view_functions[rule.endpoint](**req.view_args)
  File "app.py", line 31, in get_result
    recommender = GraphRecommender(model_dir=MODEL_DIR)
  File "/home/user2/stylehub/fashion-graph/fashion_graph/models/recommend.py", line 20, in __init__
    super().__init__(model_dir, model_config)
  File "/home/user2/stylehub/fashion-graph/fashion_graph/models/base.py", line 55, in __init__
    self.saver = tf.train.Saver()
  File "/home/user2/anaconda3/envs/graph/lib/python3.7/site-packages/tensorflow_core/python/training/saver.py", line 828, in __init__
    self.build()
  File "/home/user2/anaconda3/envs/graph/lib/python3.7/site-packages/tensorflow_core/python/training/saver.py", line 840, in build
    self._build(self._filename, build_save=True, build_restore=True)
  File "/home/user2/anaconda3/envs/graph/lib/python3.7/site-packages/tensorflow_core/python/training/saver.py", line 878, in _build
    build_restore=build_restore)
  File "/home/user2/anaconda3/envs/graph/lib/python3.7/site-packages/tensorflow_core/python/training/saver.py", line 508, in _build_internal
    restore_sequentially, reshape)
  File "/home/user2/anaconda3/envs/graph/lib/python3.7/site-packages/tensorflow_core/python/training/saver.py", line 328, in _AddRestoreOps
    restore_sequentially)
  File "/home/user2/anaconda3/envs/graph/lib/python3.7/site-packages/tensorflow_core/python/training/saver.py", line 575, in bulk_restore
    return io_ops.restore_v2(filename_tensor, names, slices, dtypes)
  File "/home/user2/anaconda3/envs/graph/lib/python3.7/site-packages/tensorflow_core/python/ops/gen_io_ops.py", line 1696, in restore_v2
    name=name)
  File "/home/user2/anaconda3/envs/graph/lib/python3.7/site-packages/tensorflow_core/python/framework/op_def_library.py", line 794, in _apply_op_helper
    op_def=op_def)
  File "/home/user2/anaconda3/envs/graph/lib/python3.7/site-packages/tensorflow_core/python/util/deprecation.py", line 507, in new_func
    return func(*args, **kwargs)
  File "/home/user2/anaconda3/envs/graph/lib/python3.7/site-packages/tensorflow_core/python/framework/ops.py", line 3357, in create_op
    attrs, op_def, compute_device)
  File "/home/user2/anaconda3/envs/graph/lib/python3.7/site-packages/tensorflow_core/python/framework/ops.py", line 3426, in _create_op_internal
    op_def=op_def)
  File "/home/user2/anaconda3/envs/graph/lib/python3.7/site-packages/tensorflow_core/python/framework/ops.py", line 1748, in __init__
    self._traceback = tf_stack.extract_stack()


During handling of the above exception, another exception occurred:

Traceback (most recent call last):
  File "/home/user2/anaconda3/envs/graph/lib/python3.7/site-packages/tensorflow_core/python/training/saver.py", line 1300, in restore
    names_to_keys = object_graph_key_mapping(save_path)
  File "/home/user2/anaconda3/envs/graph/lib/python3.7/site-packages/tensorflow_core/python/training/saver.py", line 1618, in object_graph_key_mapping
    object_graph_string = reader.get_tensor(trackable.OBJECT_GRAPH_PROTO_KEY)
  File "/home/user2/anaconda3/envs/graph/lib/python3.7/site-packages/tensorflow_core/python/pywrap_tensorflow_internal.py", line 915, in get_tensor
    return CheckpointReader_GetTensor(self, compat.as_bytes(tensor_str))
tensorflow.python.framework.errors_impl.NotFoundError: Key _CHECKPOINTABLE_OBJECT_GRAPH not found in checkpoint

During handling of the above exception, another exception occurred:

Traceback (most recent call last):
  File "/home/user2/anaconda3/envs/graph/lib/python3.7/site-packages/flask/app.py", line 2447, in wsgi_app
    response = self.full_dispatch_request()
  File "/home/user2/anaconda3/envs/graph/lib/python3.7/site-packages/flask/app.py", line 1952, in full_dispatch_request
    rv = self.handle_user_exception(e)
  File "/home/user2/anaconda3/envs/graph/lib/python3.7/site-packages/flask/app.py", line 1821, in handle_user_exception
    reraise(exc_type, exc_value, tb)
  File "/home/user2/anaconda3/envs/graph/lib/python3.7/site-packages/flask/_compat.py", line 39, in reraise
    raise value
  File "/home/user2/anaconda3/envs/graph/lib/python3.7/site-packages/flask/app.py", line 1950, in full_dispatch_request
    rv = self.dispatch_request()
  File "/home/user2/anaconda3/envs/graph/lib/python3.7/site-packages/flask/app.py", line 1936, in dispatch_request
    return self.view_functions[rule.endpoint](**req.view_args)
  File "app.py", line 31, in get_result
    recommender = GraphRecommender(model_dir=MODEL_DIR)
  File "/home/user2/stylehub/fashion-graph/fashion_graph/models/recommend.py", line 20, in __init__
    super().__init__(model_dir, model_config)
  File "/home/user2/stylehub/fashion-graph/fashion_graph/models/base.py", line 57, in __init__
    self.saver.restore(self.session, model_path)
  File "/home/user2/anaconda3/envs/graph/lib/python3.7/site-packages/tensorflow_core/python/training/saver.py", line 1306, in restore
    err, "a Variable name or other graph key that is missing")
tensorflow.python.framework.errors_impl.NotFoundError: Restoring from checkpoint failed. This is most likely due to a Variable name or other graph key that is missing from the checkpoint. Please ensure that you have not altered the graph expected based on the checkpoint. Original error:

Key compatibilitygae/gcn_10_vars/weights_n_0 not found in checkpoint
	 [[node save/RestoreV2 (defined at /home/user2/anaconda3/envs/graph/lib/python3.7/site-packages/tensorflow_core/python/framework/ops.py:1748) ]]

Original stack trace for 'save/RestoreV2':
  File "/home/user2/anaconda3/envs/graph/lib/python3.7/threading.py", line 890, in _bootstrap
    self._bootstrap_inner()
  File "/home/user2/anaconda3/envs/graph/lib/python3.7/threading.py", line 926, in _bootstrap_inner
    self.run()
  File "/home/user2/anaconda3/envs/graph/lib/python3.7/threading.py", line 870, in run
    self._target(*self._args, **self._kwargs)
  File "/home/user2/anaconda3/envs/graph/lib/python3.7/socketserver.py", line 650, in process_request_thread
    self.finish_request(request, client_address)
  File "/home/user2/anaconda3/envs/graph/lib/python3.7/socketserver.py", line 360, in finish_request
    self.RequestHandlerClass(request, client_address, self)
  File "/home/user2/anaconda3/envs/graph/lib/python3.7/socketserver.py", line 720, in __init__
    self.handle()
  File "/home/user2/anaconda3/envs/graph/lib/python3.7/site-packages/werkzeug/serving.py", line 329, in handle
    rv = BaseHTTPRequestHandler.handle(self)
  File "/home/user2/anaconda3/envs/graph/lib/python3.7/http/server.py", line 426, in handle
    self.handle_one_request()
  File "/home/user2/anaconda3/envs/graph/lib/python3.7/site-packages/werkzeug/serving.py", line 364, in handle_one_request
    return self.run_wsgi()
  File "/home/user2/anaconda3/envs/graph/lib/python3.7/site-packages/werkzeug/serving.py", line 306, in run_wsgi
    execute(self.server.app)
  File "/home/user2/anaconda3/envs/graph/lib/python3.7/site-packages/werkzeug/serving.py", line 294, in execute
    application_iter = app(environ, start_response)
  File "/home/user2/anaconda3/envs/graph/lib/python3.7/site-packages/flask/app.py", line 2464, in __call__
    return self.wsgi_app(environ, start_response)
  File "/home/user2/anaconda3/envs/graph/lib/python3.7/site-packages/flask/app.py", line 2447, in wsgi_app
    response = self.full_dispatch_request()
  File "/home/user2/anaconda3/envs/graph/lib/python3.7/site-packages/flask/app.py", line 1950, in full_dispatch_request
    rv = self.dispatch_request()
  File "/home/user2/anaconda3/envs/graph/lib/python3.7/site-packages/flask/app.py", line 1936, in dispatch_request
    return self.view_functions[rule.endpoint](**req.view_args)
  File "app.py", line 31, in get_result
    recommender = GraphRecommender(model_dir=MODEL_DIR)
  File "/home/user2/stylehub/fashion-graph/fashion_graph/models/recommend.py", line 20, in __init__
    super().__init__(model_dir, model_config)
  File "/home/user2/stylehub/fashion-graph/fashion_graph/models/base.py", line 55, in __init__
    self.saver = tf.train.Saver()
  File "/home/user2/anaconda3/envs/graph/lib/python3.7/site-packages/tensorflow_core/python/training/saver.py", line 828, in __init__
    self.build()
  File "/home/user2/anaconda3/envs/graph/lib/python3.7/site-packages/tensorflow_core/python/training/saver.py", line 840, in build
    self._build(self._filename, build_save=True, build_restore=True)
  File "/home/user2/anaconda3/envs/graph/lib/python3.7/site-packages/tensorflow_core/python/training/saver.py", line 878, in _build
    build_restore=build_restore)
  File "/home/user2/anaconda3/envs/graph/lib/python3.7/site-packages/tensorflow_core/python/training/saver.py", line 508, in _build_internal
    restore_sequentially, reshape)
  File "/home/user2/anaconda3/envs/graph/lib/python3.7/site-packages/tensorflow_core/python/training/saver.py", line 328, in _AddRestoreOps
    restore_sequentially)
  File "/home/user2/anaconda3/envs/graph/lib/python3.7/site-packages/tensorflow_core/python/training/saver.py", line 575, in bulk_restore
    return io_ops.restore_v2(filename_tensor, names, slices, dtypes)
  File "/home/user2/anaconda3/envs/graph/lib/python3.7/site-packages/tensorflow_core/python/ops/gen_io_ops.py", line 1696, in restore_v2
    name=name)
  File "/home/user2/anaconda3/envs/graph/lib/python3.7/site-packages/tensorflow_core/python/framework/op_def_library.py", line 794, in _apply_op_helper
    op_def=op_def)
  File "/home/user2/anaconda3/envs/graph/lib/python3.7/site-packages/tensorflow_core/python/util/deprecation.py", line 507, in new_func
    return func(*args, **kwargs)
  File "/home/user2/anaconda3/envs/graph/lib/python3.7/site-packages/tensorflow_core/python/framework/ops.py", line 3357, in create_op
    attrs, op_def, compute_device)
  File "/home/user2/anaconda3/envs/graph/lib/python3.7/site-packages/tensorflow_core/python/framework/ops.py", line 3426, in _create_op_internal
    op_def=op_def)
  File "/home/user2/anaconda3/envs/graph/lib/python3.7/site-packages/tensorflow_core/python/framework/ops.py", line 1748, in __init__
    self._traceback = tf_stack.extract_stack()

54.86.50.139 - - [03/Aug/2021 17:21:08] "[1m[35mPOST /styling HTTP/1.1[0m" 500 -
2021-08-03 17:26:21.307370: W tensorflow/core/framework/op_kernel.cc:1651] OP_REQUIRES failed at save_restore_v2_ops.cc:184 : Not found: Key compatibilitygae/gcn_13_vars/weights_n_0 not found in checkpoint
/home/user2/anaconda3/envs/graph/lib/python3.7/site-packages/tensorflow_core/python/framework/indexed_slices.py:424: UserWarning: Converting sparse IndexedSlices to a dense Tensor of unknown shape. This may consume a large amount of memory.
  "Converting sparse IndexedSlices to a dense Tensor of unknown shape. "
[2021-08-03 17:26:21,323] ERROR in app: Exception on /styling [POST]
Traceback (most recent call last):
  File "/home/user2/anaconda3/envs/graph/lib/python3.7/site-packages/tensorflow_core/python/client/session.py", line 1365, in _do_call
    return fn(*args)
  File "/home/user2/anaconda3/envs/graph/lib/python3.7/site-packages/tensorflow_core/python/client/session.py", line 1350, in _run_fn
    target_list, run_metadata)
  File "/home/user2/anaconda3/envs/graph/lib/python3.7/site-packages/tensorflow_core/python/client/session.py", line 1443, in _call_tf_sessionrun
    run_metadata)
tensorflow.python.framework.errors_impl.NotFoundError: Key compatibilitygae/gcn_13_vars/weights_n_0 not found in checkpoint
	 [[{{node save/RestoreV2}}]]

During handling of the above exception, another exception occurred:

Traceback (most recent call last):
  File "/home/user2/anaconda3/envs/graph/lib/python3.7/site-packages/tensorflow_core/python/training/saver.py", line 1290, in restore
    {self.saver_def.filename_tensor_name: save_path})
  File "/home/user2/anaconda3/envs/graph/lib/python3.7/site-packages/tensorflow_core/python/client/session.py", line 956, in run
    run_metadata_ptr)
  File "/home/user2/anaconda3/envs/graph/lib/python3.7/site-packages/tensorflow_core/python/client/session.py", line 1180, in _run
    feed_dict_tensor, options, run_metadata)
  File "/home/user2/anaconda3/envs/graph/lib/python3.7/site-packages/tensorflow_core/python/client/session.py", line 1359, in _do_run
    run_metadata)
  File "/home/user2/anaconda3/envs/graph/lib/python3.7/site-packages/tensorflow_core/python/client/session.py", line 1384, in _do_call
    raise type(e)(node_def, op, message)
tensorflow.python.framework.errors_impl.NotFoundError: Key compatibilitygae/gcn_13_vars/weights_n_0 not found in checkpoint
	 [[node save/RestoreV2 (defined at /home/user2/anaconda3/envs/graph/lib/python3.7/site-packages/tensorflow_core/python/framework/ops.py:1748) ]]

Original stack trace for 'save/RestoreV2':
  File "/home/user2/anaconda3/envs/graph/lib/python3.7/threading.py", line 890, in _bootstrap
    self._bootstrap_inner()
  File "/home/user2/anaconda3/envs/graph/lib/python3.7/threading.py", line 926, in _bootstrap_inner
    self.run()
  File "/home/user2/anaconda3/envs/graph/lib/python3.7/threading.py", line 870, in run
    self._target(*self._args, **self._kwargs)
  File "/home/user2/anaconda3/envs/graph/lib/python3.7/socketserver.py", line 650, in process_request_thread
    self.finish_request(request, client_address)
  File "/home/user2/anaconda3/envs/graph/lib/python3.7/socketserver.py", line 360, in finish_request
    self.RequestHandlerClass(request, client_address, self)
  File "/home/user2/anaconda3/envs/graph/lib/python3.7/socketserver.py", line 720, in __init__
    self.handle()
  File "/home/user2/anaconda3/envs/graph/lib/python3.7/site-packages/werkzeug/serving.py", line 329, in handle
    rv = BaseHTTPRequestHandler.handle(self)
  File "/home/user2/anaconda3/envs/graph/lib/python3.7/http/server.py", line 426, in handle
    self.handle_one_request()
  File "/home/user2/anaconda3/envs/graph/lib/python3.7/site-packages/werkzeug/serving.py", line 364, in handle_one_request
    return self.run_wsgi()
  File "/home/user2/anaconda3/envs/graph/lib/python3.7/site-packages/werkzeug/serving.py", line 306, in run_wsgi
    execute(self.server.app)
  File "/home/user2/anaconda3/envs/graph/lib/python3.7/site-packages/werkzeug/serving.py", line 294, in execute
    application_iter = app(environ, start_response)
  File "/home/user2/anaconda3/envs/graph/lib/python3.7/site-packages/flask/app.py", line 2464, in __call__
    return self.wsgi_app(environ, start_response)
  File "/home/user2/anaconda3/envs/graph/lib/python3.7/site-packages/flask/app.py", line 2447, in wsgi_app
    response = self.full_dispatch_request()
  File "/home/user2/anaconda3/envs/graph/lib/python3.7/site-packages/flask/app.py", line 1950, in full_dispatch_request
    rv = self.dispatch_request()
  File "/home/user2/anaconda3/envs/graph/lib/python3.7/site-packages/flask/app.py", line 1936, in dispatch_request
    return self.view_functions[rule.endpoint](**req.view_args)
  File "app.py", line 31, in get_result
    recommender = GraphRecommender(model_dir=MODEL_DIR)
  File "/home/user2/stylehub/fashion-graph/fashion_graph/models/recommend.py", line 20, in __init__
    super().__init__(model_dir, model_config)
  File "/home/user2/stylehub/fashion-graph/fashion_graph/models/base.py", line 55, in __init__
    self.saver = tf.train.Saver()
  File "/home/user2/anaconda3/envs/graph/lib/python3.7/site-packages/tensorflow_core/python/training/saver.py", line 828, in __init__
    self.build()
  File "/home/user2/anaconda3/envs/graph/lib/python3.7/site-packages/tensorflow_core/python/training/saver.py", line 840, in build
    self._build(self._filename, build_save=True, build_restore=True)
  File "/home/user2/anaconda3/envs/graph/lib/python3.7/site-packages/tensorflow_core/python/training/saver.py", line 878, in _build
    build_restore=build_restore)
  File "/home/user2/anaconda3/envs/graph/lib/python3.7/site-packages/tensorflow_core/python/training/saver.py", line 508, in _build_internal
    restore_sequentially, reshape)
  File "/home/user2/anaconda3/envs/graph/lib/python3.7/site-packages/tensorflow_core/python/training/saver.py", line 328, in _AddRestoreOps
    restore_sequentially)
  File "/home/user2/anaconda3/envs/graph/lib/python3.7/site-packages/tensorflow_core/python/training/saver.py", line 575, in bulk_restore
    return io_ops.restore_v2(filename_tensor, names, slices, dtypes)
  File "/home/user2/anaconda3/envs/graph/lib/python3.7/site-packages/tensorflow_core/python/ops/gen_io_ops.py", line 1696, in restore_v2
    name=name)
  File "/home/user2/anaconda3/envs/graph/lib/python3.7/site-packages/tensorflow_core/python/framework/op_def_library.py", line 794, in _apply_op_helper
    op_def=op_def)
  File "/home/user2/anaconda3/envs/graph/lib/python3.7/site-packages/tensorflow_core/python/util/deprecation.py", line 507, in new_func
    return func(*args, **kwargs)
  File "/home/user2/anaconda3/envs/graph/lib/python3.7/site-packages/tensorflow_core/python/framework/ops.py", line 3357, in create_op
    attrs, op_def, compute_device)
  File "/home/user2/anaconda3/envs/graph/lib/python3.7/site-packages/tensorflow_core/python/framework/ops.py", line 3426, in _create_op_internal
    op_def=op_def)
  File "/home/user2/anaconda3/envs/graph/lib/python3.7/site-packages/tensorflow_core/python/framework/ops.py", line 1748, in __init__
    self._traceback = tf_stack.extract_stack()


During handling of the above exception, another exception occurred:

Traceback (most recent call last):
  File "/home/user2/anaconda3/envs/graph/lib/python3.7/site-packages/tensorflow_core/python/training/saver.py", line 1300, in restore
    names_to_keys = object_graph_key_mapping(save_path)
  File "/home/user2/anaconda3/envs/graph/lib/python3.7/site-packages/tensorflow_core/python/training/saver.py", line 1618, in object_graph_key_mapping
    object_graph_string = reader.get_tensor(trackable.OBJECT_GRAPH_PROTO_KEY)
  File "/home/user2/anaconda3/envs/graph/lib/python3.7/site-packages/tensorflow_core/python/pywrap_tensorflow_internal.py", line 915, in get_tensor
    return CheckpointReader_GetTensor(self, compat.as_bytes(tensor_str))
tensorflow.python.framework.errors_impl.NotFoundError: Key _CHECKPOINTABLE_OBJECT_GRAPH not found in checkpoint

During handling of the above exception, another exception occurred:

Traceback (most recent call last):
  File "/home/user2/anaconda3/envs/graph/lib/python3.7/site-packages/flask/app.py", line 2447, in wsgi_app
    response = self.full_dispatch_request()
  File "/home/user2/anaconda3/envs/graph/lib/python3.7/site-packages/flask/app.py", line 1952, in full_dispatch_request
    rv = self.handle_user_exception(e)
  File "/home/user2/anaconda3/envs/graph/lib/python3.7/site-packages/flask/app.py", line 1821, in handle_user_exception
    reraise(exc_type, exc_value, tb)
  File "/home/user2/anaconda3/envs/graph/lib/python3.7/site-packages/flask/_compat.py", line 39, in reraise
    raise value
  File "/home/user2/anaconda3/envs/graph/lib/python3.7/site-packages/flask/app.py", line 1950, in full_dispatch_request
    rv = self.dispatch_request()
  File "/home/user2/anaconda3/envs/graph/lib/python3.7/site-packages/flask/app.py", line 1936, in dispatch_request
    return self.view_functions[rule.endpoint](**req.view_args)
  File "app.py", line 31, in get_result
    recommender = GraphRecommender(model_dir=MODEL_DIR)
  File "/home/user2/stylehub/fashion-graph/fashion_graph/models/recommend.py", line 20, in __init__
    super().__init__(model_dir, model_config)
  File "/home/user2/stylehub/fashion-graph/fashion_graph/models/base.py", line 57, in __init__
    self.saver.restore(self.session, model_path)
  File "/home/user2/anaconda3/envs/graph/lib/python3.7/site-packages/tensorflow_core/python/training/saver.py", line 1306, in restore
    err, "a Variable name or other graph key that is missing")
tensorflow.python.framework.errors_impl.NotFoundError: Restoring from checkpoint failed. This is most likely due to a Variable name or other graph key that is missing from the checkpoint. Please ensure that you have not altered the graph expected based on the checkpoint. Original error:

Key compatibilitygae/gcn_13_vars/weights_n_0 not found in checkpoint
	 [[node save/RestoreV2 (defined at /home/user2/anaconda3/envs/graph/lib/python3.7/site-packages/tensorflow_core/python/framework/ops.py:1748) ]]

Original stack trace for 'save/RestoreV2':
  File "/home/user2/anaconda3/envs/graph/lib/python3.7/threading.py", line 890, in _bootstrap
    self._bootstrap_inner()
  File "/home/user2/anaconda3/envs/graph/lib/python3.7/threading.py", line 926, in _bootstrap_inner
    self.run()
  File "/home/user2/anaconda3/envs/graph/lib/python3.7/threading.py", line 870, in run
    self._target(*self._args, **self._kwargs)
  File "/home/user2/anaconda3/envs/graph/lib/python3.7/socketserver.py", line 650, in process_request_thread
    self.finish_request(request, client_address)
  File "/home/user2/anaconda3/envs/graph/lib/python3.7/socketserver.py", line 360, in finish_request
    self.RequestHandlerClass(request, client_address, self)
  File "/home/user2/anaconda3/envs/graph/lib/python3.7/socketserver.py", line 720, in __init__
    self.handle()
  File "/home/user2/anaconda3/envs/graph/lib/python3.7/site-packages/werkzeug/serving.py", line 329, in handle
    rv = BaseHTTPRequestHandler.handle(self)
  File "/home/user2/anaconda3/envs/graph/lib/python3.7/http/server.py", line 426, in handle
    self.handle_one_request()
  File "/home/user2/anaconda3/envs/graph/lib/python3.7/site-packages/werkzeug/serving.py", line 364, in handle_one_request
    return self.run_wsgi()
  File "/home/user2/anaconda3/envs/graph/lib/python3.7/site-packages/werkzeug/serving.py", line 306, in run_wsgi
    execute(self.server.app)
  File "/home/user2/anaconda3/envs/graph/lib/python3.7/site-packages/werkzeug/serving.py", line 294, in execute
    application_iter = app(environ, start_response)
  File "/home/user2/anaconda3/envs/graph/lib/python3.7/site-packages/flask/app.py", line 2464, in __call__
    return self.wsgi_app(environ, start_response)
  File "/home/user2/anaconda3/envs/graph/lib/python3.7/site-packages/flask/app.py", line 2447, in wsgi_app
    response = self.full_dispatch_request()
  File "/home/user2/anaconda3/envs/graph/lib/python3.7/site-packages/flask/app.py", line 1950, in full_dispatch_request
    rv = self.dispatch_request()
  File "/home/user2/anaconda3/envs/graph/lib/python3.7/site-packages/flask/app.py", line 1936, in dispatch_request
    return self.view_functions[rule.endpoint](**req.view_args)
  File "app.py", line 31, in get_result
    recommender = GraphRecommender(model_dir=MODEL_DIR)
  File "/home/user2/stylehub/fashion-graph/fashion_graph/models/recommend.py", line 20, in __init__
    super().__init__(model_dir, model_config)
  File "/home/user2/stylehub/fashion-graph/fashion_graph/models/base.py", line 55, in __init__
    self.saver = tf.train.Saver()
  File "/home/user2/anaconda3/envs/graph/lib/python3.7/site-packages/tensorflow_core/python/training/saver.py", line 828, in __init__
    self.build()
  File "/home/user2/anaconda3/envs/graph/lib/python3.7/site-packages/tensorflow_core/python/training/saver.py", line 840, in build
    self._build(self._filename, build_save=True, build_restore=True)
  File "/home/user2/anaconda3/envs/graph/lib/python3.7/site-packages/tensorflow_core/python/training/saver.py", line 878, in _build
    build_restore=build_restore)
  File "/home/user2/anaconda3/envs/graph/lib/python3.7/site-packages/tensorflow_core/python/training/saver.py", line 508, in _build_internal
    restore_sequentially, reshape)
  File "/home/user2/anaconda3/envs/graph/lib/python3.7/site-packages/tensorflow_core/python/training/saver.py", line 328, in _AddRestoreOps
    restore_sequentially)
  File "/home/user2/anaconda3/envs/graph/lib/python3.7/site-packages/tensorflow_core/python/training/saver.py", line 575, in bulk_restore
    return io_ops.restore_v2(filename_tensor, names, slices, dtypes)
  File "/home/user2/anaconda3/envs/graph/lib/python3.7/site-packages/tensorflow_core/python/ops/gen_io_ops.py", line 1696, in restore_v2
    name=name)
  File "/home/user2/anaconda3/envs/graph/lib/python3.7/site-packages/tensorflow_core/python/framework/op_def_library.py", line 794, in _apply_op_helper
    op_def=op_def)
  File "/home/user2/anaconda3/envs/graph/lib/python3.7/site-packages/tensorflow_core/python/util/deprecation.py", line 507, in new_func
    return func(*args, **kwargs)
  File "/home/user2/anaconda3/envs/graph/lib/python3.7/site-packages/tensorflow_core/python/framework/ops.py", line 3357, in create_op
    attrs, op_def, compute_device)
  File "/home/user2/anaconda3/envs/graph/lib/python3.7/site-packages/tensorflow_core/python/framework/ops.py", line 3426, in _create_op_internal
    op_def=op_def)
  File "/home/user2/anaconda3/envs/graph/lib/python3.7/site-packages/tensorflow_core/python/framework/ops.py", line 1748, in __init__
    self._traceback = tf_stack.extract_stack()

54.86.50.139 - - [03/Aug/2021 17:26:21] "[1m[35mPOST /styling HTTP/1.1[0m" 500 -
192.241.221.8 - - [03/Aug/2021 17:32:33] code 400, message Bad request version ('À\x14À')
192.241.221.8 - - [03/Aug/2021 17:32:33] "[1m[35m c  _R>S¬LOd¿&À¢a×AìÏ]ÐKBO1°3l  ÀÀÀÀ	ÀÀ[0m" HTTPStatus.BAD_REQUEST -
 * Serving Flask app "app" (lazy loading)
 * Environment: production
   WARNING: This is a development server. Do not use it in a production deployment.
   Use a production WSGI server instead.
 * Debug mode: off
 * Running on http://14.49.45.139:8443/ (Press CTRL+C to quit)
[2021-08-03 17:47:02,487] ERROR in app: Exception on /styling [POST]
Traceback (most recent call last):
  File "/home/user2/anaconda3/envs/graph/lib/python3.7/site-packages/flask/app.py", line 2447, in wsgi_app
    response = self.full_dispatch_request()
  File "/home/user2/anaconda3/envs/graph/lib/python3.7/site-packages/flask/app.py", line 1952, in full_dispatch_request
    rv = self.handle_user_exception(e)
  File "/home/user2/anaconda3/envs/graph/lib/python3.7/site-packages/flask/app.py", line 1821, in handle_user_exception
    reraise(exc_type, exc_value, tb)
  File "/home/user2/anaconda3/envs/graph/lib/python3.7/site-packages/flask/_compat.py", line 39, in reraise
    raise value
  File "/home/user2/anaconda3/envs/graph/lib/python3.7/site-packages/flask/app.py", line 1950, in full_dispatch_request
    rv = self.dispatch_request()
  File "/home/user2/anaconda3/envs/graph/lib/python3.7/site-packages/flask/app.py", line 1936, in dispatch_request
    return self.view_functions[rule.endpoint](**req.view_args)
  File "app.py", line 31, in get_result
    recommender = GraphRecommender(model_dir=MODEL_DIR, model_config=tf.ConfigProto(allow_soft_placement=True, log_device_placement=True))
NameError: name 'tf' is not defined
54.86.50.139 - - [03/Aug/2021 17:47:02] "[1m[35mPOST /styling HTTP/1.1[0m" 500 -
